Workbook

Sheet Bank Reconciliation Statement
A1: June 2026 Bank Reconciliation
A2: Reconciled from the cleaned bank statement and GL cash extract
A3: Reconciliation bridge | B3: Amount | C3: Count
A4: Bank activity total | B4: =SUM(Bankl[Amount]) -> 222907.3 | C4: 122
A5: GL activity total | B5: =SUM(Cash[Amount]) -> 253663.77 | C5: 121
A6: Raw GL less bank | B6: =B5-B4 -> 30756.47
A7: Less: GL-only transactions | B7: =-SUMIFS(Cash[Amount],Cash[Reconciliation Status],"Missing from Bank") -> -31253.55 | C7: =COUNTIF(Cash[Reconciliation Status],"Missing from Bank") -> 6
A8: Add: Bank-only transactions | B8: =SUMIFS(Bankl[Amount],Bankl[Reconciliation Status],"Missing from GL") -> 497.43 | C8: =COUNTIF(Bankl[Reconciliation Status],"Missing from GL") -> 7
A9: Add: Bank–GL amount differences | B9: =SUMIFS(Bankl[Difference],Bankl[Reconciliation Status],"Difference") -> -0.35 | C9: =COUNTIF(Bankl[Reconciliation Status],"Difference") -> 8
A10: Adjusted GL activity | B10: =B5+B7+B8+B9 -> 222907.3
A11: Unreconciled variance | B11: =B4-B10 -> 0
A13: Exception Type | B13: Date | C13: Reference | D13: Description / Memo | E13: Bank Amount | F13: GL Amount | G13: Suggested Action
A14: Amount Difference | B14: 46177 | C14: REF40826 | D14: EFT BELL CDA PAYMENT REF40826 | E14: -4183.58 | F14: -4183.67 | G14: Verify source and adjust GL to bank amount; bank–GL variance $0.09
A15: Amount Difference | B15: 46183 | C15: REF40929 | D15: PAD GFL ENVIRONMENTAL SVC REF40929 | E15: -743.6 | F15: -743.29 | G15: Verify source and adjust GL to bank amount; bank–GL variance -$0.31
A16: Amount Difference | B16: 46190 | C16: REF40833 | D16: PAD SHELL FLEET CARD SVC REF40833 | E16: -2411.46 | F16: -2411.28 | G16: Verify source and adjust GL to bank amount; bank–GL variance -$0.18
A17: Bank Only | B17: 46191 | C17: NSF-0618 | D17: NSF RETURNED ITEM FEE | E17: -48 | G17: Post bank fee/charge to the GL
A18: Amount Difference | B18: 46191 | C18: REF40918 | D18: PAD MILTON HYDRO UTIL REF40918 | E18: -1154.68 | F18: -1154.82 | G18: Verify source and adjust GL to bank amount; bank–GL variance $0.14
A19: Amount Difference | B19: 46195 | C19: REF40901 | D19: EFT ANIXTER CDA SUPPLY REF40901 | E19: -9274.79 | F19: -9274.16 | G19: Verify source and adjust GL to bank amount; bank–GL variance -$0.63
A20: Bank Only | B20: 46195 | C20: MER-0622 | D20: MERCHANT PROCESSING FEE MONERIS | E20: -389.44 | G20: Post bank fee/charge to the GL
A21: Amount Difference | B21: 46195 | C21: REF40884 | D21: PAD INTACT INSURANCE PREM REF40884 | E21: -1887.08 | F21: -1887.53 | G21: Verify source and adjust GL to bank amount; bank–GL variance $0.45
A22: Amount Difference | B22: 46195 | C22: REF40865 | D22: PAD UNITED RENTALS INC REF40865 | E22: -6649.18 | F22: -6648.91 | G22: Verify source and adjust GL to bank amount; bank–GL variance -$0.27
A23: Amount Difference | B23: 46197 | C23: REF40852 | D23: EFT WESCO DIST CANADA REF40852 | E23: -13902.08 | F23: -13902.44 | G23: Verify source and adjust GL to bank amount; bank–GL variance $0.36
A24: Bank Only | B24: 46198 | C24: PAD-7719 | D24: PRE-AUTH DEBIT UNKNOWN ORIG 7719 | E24: -1260 | G24: Investigate the bank-only transaction and post if valid
A25: Bank Only | B25: 46199 | C25: ETR-T4X99A | D25: E-TRANSFER RECEIVED T4X99A | E25: 2150 | G25: Post bank fee/charge to the GL
A26: Bank Only | B26: 46203 | C26: INT-JUN | D26: INTEREST EARNED | E26: 214.87 | G26: Post bank interest income to the GL
A27: Bank Only | B27: 46203 | C27: SVC-JUN | D27: MONTHLY ACCOUNT FEE | E27: -125 | G27: Post bank fee/charge to the GL
A28: Bank Only | B28: 46203 | C28: WIRE-FEE | D28: SERVICE CHARGE - WIRE PAYMENT | E28: -45 | G28: Post bank fee/charge to the GL
A29: GL Only | B29: 46199 | C29: CHQ#1079 | D29: Ditch Witch of Ontario — parts invoice | F29: -7412.66 | G29: Outstanding payment—confirm it cleared after June
A30: GL Only | B30: 46202 | C30: CHQ#1081 | D30: Region of Halton — road permit fees | F30: -2340.55 | G30: Outstanding payment—confirm it cleared after June
A31: GL Only | B31: 46202 | C31: CHQ#1080 | D31: Vermeer Canada — drill head rebuild | F31: -15890.23 | G31: Outstanding payment—confirm it cleared after June
A32: GL Only | B32: 46203 | C32: CHQ#1082 | D32: Brandt Tractor Ltd — service invoice | F32: -4178.09 | G32: Outstanding payment—confirm it cleared after June
A33: GL Only | B33: 46203 | C33: REF40957 | D33: Cogeco underground build | F33: 12764.31 | G33: Deposit in transit—confirm bank receipt after June
A34: GL Only | B34: 46203 | C34: REF40947 | D34: Rogers Communications — progress billing | F34: 48310.77 | G34: Deposit in transit—confirm bank receipt after June

Sheet bank_statement_jun2026
A1: Date | B1: Description | C1: Reference | D1: Amount | E1: GL MATCH | F1: Reconciliation Status | G1: Difference | H1: Action / Notes
A2: 46174 | B2: CHEQUE 1042 | C2: CHQ#1042 | D2: -10230.18 | E2: =_xlfn.XLOOKUP(C2,gl_cash_extract_jun2026!D:D,gl_cash_extract_jun2026!E:E,"Not Found") -> -10230.18 | F2: =IF(E2="Not Found","Missing from GL",IF(D2=E2,"Matched","Difference")) -> Matched | G2: =IF(ISNUMBER(E2),ROUND(D2-E2,2),"") -> 0
A3: 46174 | B3: CHEQUE 1064 | C3: CHQ#1064 | D3: -8067.99 | E3: =_xlfn.XLOOKUP(C3,gl_cash_extract_jun2026!D:D,gl_cash_extract_jun2026!E:E,"Not Found") -> -8067.99 | F3: =IF(E3="Not Found","Missing from GL",IF(D3=E3,"Matched","Difference")) -> Matched | G3: =IF(ISNUMBER(E3),ROUND(D3-E3,2),"") -> 0
A4: 46174 | B4: DEP ROGERS COMM AP REF40771 | C4: REF40771 | D4: 88790.68 | E4: =_xlfn.XLOOKUP(C4,gl_cash_extract_jun2026!D:D,gl_cash_extract_jun2026!E:E,"Not Found") -> 88790.68 | F4: =IF(E4="Not Found","Missing from GL",IF(D4=E4,"Matched","Difference")) -> Matched | G4: =IF(ISNUMBER(E4),ROUND(D4-E4,2),"") -> 0
A5: 46174 | B5: PAD SHELL FLEET REF40144 | C5: REF40144 | D5: -12217.56 | E5: =_xlfn.XLOOKUP(C5,gl_cash_extract_jun2026!D:D,gl_cash_extract_jun2026!E:E,"Not Found") -> -12217.56 | F5: =IF(E5="Not Found","Missing from GL",IF(D5=E5,"Matched","Difference")) -> Matched | G5: =IF(ISNUMBER(E5),ROUND(D5-E5,2),"") -> 0
A6: 46175 | B6: CHEQUE 1051 | C6: CHQ#1051 | D6: -17040.77 | E6: =_xlfn.XLOOKUP(C6,gl_cash_extract_jun2026!D:D,gl_cash_extract_jun2026!E:E,"Not Found") -> -17040.77 | F6: =IF(E6="Not Found","Missing from GL",IF(D6=E6,"Matched","Difference")) -> Matched | G6: =IF(ISNUMBER(E6),ROUND(D6-E6,2),"") -> 0
A7: 46175 | B7: DEP TELUS COMM AP REF40191 | C7: REF40191 | D7: 88411.47 | E7: =_xlfn.XLOOKUP(C7,gl_cash_extract_jun2026!D:D,gl_cash_extract_jun2026!E:E,"Not Found") -> 88411.47 | F7: =IF(E7="Not Found","Missing from GL",IF(D7=E7,"Matched","Difference")) -> Matched | G7: =IF(ISNUMBER(E7),ROUND(D7-E7,2),"") -> 0
A8: 46175 | B8: PAD ENTERPRISE FLEET REF40486 | C8: REF40486 | D8: -5365.64 | E8: =_xlfn.XLOOKUP(C8,gl_cash_extract_jun2026!D:D,gl_cash_extract_jun2026!E:E,"Not Found") -> -5365.64 | F8: =IF(E8="Not Found","Missing from GL",IF(D8=E8,"Matched","Difference")) -> Matched | G8: =IF(ISNUMBER(E8),ROUND(D8-E8,2),"") -> 0
A9: 46176 | B9: CHEQUE 1048 | C9: CHQ#1048 | D9: -21094.19 | E9: =_xlfn.XLOOKUP(C9,gl_cash_extract_jun2026!D:D,gl_cash_extract_jun2026!E:E,"Not Found") -> -21094.19 | F9: =IF(E9="Not Found","Missing from GL",IF(D9=E9,"Matched","Difference")) -> Matched | G9: =IF(ISNUMBER(E9),ROUND(D9-E9,2),"") -> 0
A10: 46176 | B10: DEP ROGERS COMM AP REF40398 | C10: REF40398 | D10: 102367.19 | E10: =_xlfn.XLOOKUP(C10,gl_cash_extract_jun2026!D:D,gl_cash_extract_jun2026!E:E,"Not Found") -> 102367.19 | F10: =IF(E10="Not Found","Missing from GL",IF(D10=E10,"Matched","Difference")) -> Matched | G10: =IF(ISNUMBER(E10),ROUND(D10-E10,2),"") -> 0
A11: 46176 | B11: EFT BRANDT TRACTOR REF40276 | C11: REF40276 | D11: -12316.92 | E11: =_xlfn.XLOOKUP(C11,gl_cash_extract_jun2026!D:D,gl_cash_extract_jun2026!E:E,"Not Found") -> -12316.92 | F11: =IF(E11="Not Found","Missing from GL",IF(D11=E11,"Matched","Difference")) -> Matched | G11: =IF(ISNUMBER(E11),ROUND(D11-E11,2),"") -> 0
A12: 46176 | B12: PAD MILTON HYDRO REF40442 | C12: REF40442 | D12: -20094.18 | E12: =_xlfn.XLOOKUP(C12,gl_cash_extract_jun2026!D:D,gl_cash_extract_jun2026!E:E,"Not Found") -> -20094.18 | F12: =IF(E12="Not Found","Missing from GL",IF(D12=E12,"Matched","Difference")) -> Matched | G12: =IF(ISNUMBER(E12),ROUND(D12-E12,2),"") -> 0
A13: 46177 | B13: EFT BELL CDA PAYMENT REF40826 | C13: REF40826 | D13: -4183.58 | E13: =_xlfn.XLOOKUP(C13,gl_cash_extract_jun2026!D:D,gl_cash_extract_jun2026!E:E,"Not Found") -> -4183.67 | F13: =IF(E13="Not Found","Missing from GL",IF(D13=E13,"Matched","Difference")) -> Difference | G13: =IF(ISNUMBER(E13),ROUND(D13-E13,2),"") -> 0.09 | H13: Verify source and adjust GL to bank amount; bank–GL variance $0.09
A14: 46177 | B14: EFT BRANDT TRACTOR REF40587 | C14: REF40587 | D14: -6479.58 | E14: =_xlfn.XLOOKUP(C14,gl_cash_extract_jun2026!D:D,gl_cash_extract_jun2026!E:E,"Not Found") -> -6479.58 | F14: =IF(E14="Not Found","Missing from GL",IF(D14=E14,"Matched","Difference")) -> Matched | G14: =IF(ISNUMBER(E14),ROUND(D14-E14,2),"") -> 0
A15: 46177 | B15: EFT WESCO DIST REF40326 | C15: REF40326 | D15: -12272.98 | E15: =_xlfn.XLOOKUP(C15,gl_cash_extract_jun2026!D:D,gl_cash_extract_jun2026!E:E,"Not Found") -> -12272.98 | F15: =IF(E15="Not Found","Missing from GL",IF(D15=E15,"Matched","Difference")) -> Matched | G15: =IF(ISNUMBER(E15),ROUND(D15-E15,2),"") -> 0
A16: 46177 | B16: PAD SHELL FLEET REF40128 | C16: REF40128 | D16: -3503.79 | E16: =_xlfn.XLOOKUP(C16,gl_cash_extract_jun2026!D:D,gl_cash_extract_jun2026!E:E,"Not Found") -> -3503.79 | F16: =IF(E16="Not Found","Missing from GL",IF(D16=E16,"Matched","Difference")) -> Matched | G16: =IF(ISNUMBER(E16),ROUND(D16-E16,2),"") -> 0
A17: 46178 | B17: DEP BELL CDA AP REF40634 | C17: REF40634 | D17: 77425.86 | E17: =_xlfn.XLOOKUP(C17,gl_cash_extract_jun2026!D:D,gl_cash_extract_jun2026!E:E,"Not Found") -> 77425.86 | F17: =IF(E17="Not Found","Missing from GL",IF(D17=E17,"Matched","Difference")) -> Matched | G17: =IF(ISNUMBER(E17),ROUND(D17-E17,2),"") -> 0
A18: 46178 | B18: PAD GFL ENVIRONMENTAL REF40334 | C18: REF40334 | D18: -14685.67 | E18: =_xlfn.XLOOKUP(C18,gl_cash_extract_jun2026!D:D,gl_cash_extract_jun2026!E:E,"Not Found") -> -14685.67 | F18: =IF(E18="Not Found","Missing from GL",IF(D18=E18,"Matched","Difference")) -> Matched | G18: =IF(ISNUMBER(E18),ROUND(D18-E18,2),"") -> 0
A19: 46178 | B19: PAD SHELL FLEET REF40539 | C19: REF40539 | D19: -6506.94 | E19: =_xlfn.XLOOKUP(C19,gl_cash_extract_jun2026!D:D,gl_cash_extract_jun2026!E:E,"Not Found") -> -6506.94 | F19: =IF(E19="Not Found","Missing from GL",IF(D19=E19,"Matched","Difference")) -> Matched | G19: =IF(ISNUMBER(E19),ROUND(D19-E19,2),"") -> 0
A20: 46181 | B20: CHEQUE 1050 | C20: CHQ#1050 | D20: -3062.32 | E20: =_xlfn.XLOOKUP(C20,gl_cash_extract_jun2026!D:D,gl_cash_extract_jun2026!E:E,"Not Found") -> -3062.32 | F20: =IF(E20="Not Found","Missing from GL",IF(D20=E20,"Matched","Difference")) -> Matched | G20: =IF(ISNUMBER(E20),ROUND(D20-E20,2),"") -> 0
A21: 46181 | B21: CHEQUE 1053 | C21: CHQ#1053 | D21: -19414.58 | E21: =_xlfn.XLOOKUP(C21,gl_cash_extract_jun2026!D:D,gl_cash_extract_jun2026!E:E,"Not Found") -> -19414.58 | F21: =IF(E21="Not Found","Missing from GL",IF(D21=E21,"Matched","Difference")) -> Matched | G21: =IF(ISNUMBER(E21),ROUND(D21-E21,2),"") -> 0
A22: 46181 | B22: CHEQUE 1058 | C22: CHQ#1058 | D22: -2088.26 | E22: =_xlfn.XLOOKUP(C22,gl_cash_extract_jun2026!D:D,gl_cash_extract_jun2026!E:E,"Not Found") -> -2088.26 | F22: =IF(E22="Not Found","Missing from GL",IF(D22=E22,"Matched","Difference")) -> Matched | G22: =IF(ISNUMBER(E22),ROUND(D22-E22,2),"") -> 0
A23: 46181 | B23: CHEQUE 1063 | C23: CHQ#1063 | D23: -20631.69 | E23: =_xlfn.XLOOKUP(C23,gl_cash_extract_jun2026!D:D,gl_cash_extract_jun2026!E:E,"Not Found") -> -20631.69 | F23: =IF(E23="Not Found","Missing from GL",IF(D23=E23,"Matched","Difference")) -> Matched | G23: =IF(ISNUMBER(E23),ROUND(D23-E23,2),"") -> 0
A24: 46181 | B24: DEP BELL CDA AP REF40527 | C24: REF40527 | D24: 109123.56 | E24: =_xlfn.XLOOKUP(C24,gl_cash_extract_jun2026!D:D,gl_cash_extract_jun2026!E:E,"Not Found") -> 109123.56 | F24: =IF(E24="Not Found","Missing from GL",IF(D24=E24,"Matched","Difference")) -> Matched | G24: =IF(ISNUMBER(E24),ROUND(D24-E24,2),"") -> 0
A25: 46181 | B25: DEP BELL CDA AP REF40561 | C25: REF40561 | D25: 104277.78 | E25: =_xlfn.XLOOKUP(C25,gl_cash_extract_jun2026!D:D,gl_cash_extract_jun2026!E:E,"Not Found") -> 104277.78 | F25: =IF(E25="Not Found","Missing from GL",IF(D25=E25,"Matched","Difference")) -> Matched | G25: =IF(ISNUMBER(E25),ROUND(D25-E25,2),"") -> 0
... A42: 46182 | B42: PAD SHELL FLEET REF40147 | C42: REF40147 | D42: -10880.16 | E42: =_xlfn.XLOOKUP(C42,gl_cash_extract_jun2026!D:D,gl_cash_extract_jun2026!E:E,"Not Found") -> -10880.16 | F42: =IF(E42="Not Found","Missing from GL",IF(D42=E42,"Matched","Difference")) -> Matched | G42: =IF(ISNUMBER(E42),ROUND(D42-E42,2),"") -> 0
A43: 46183 | B43: PAD GFL ENVIRONMENTAL SVC REF40929 | C43: REF40929 | D43: -743.6 | E43: =_xlfn.XLOOKUP(C43,gl_cash_extract_jun2026!D:D,gl_cash_extract_jun2026!E:E,"Not Found") -> -743.29 | F43: =IF(E43="Not Found","Missing from GL",IF(D43=E43,"Matched","Difference")) -> Difference | G43: =IF(ISNUMBER(E43),ROUND(D43-E43,2),"") -> -0.31 | H43: Verify source and adjust GL to bank amount; bank–GL variance -$0.31
A44: 46184 | B44: CHEQUE 1046 | C44: CHQ#1046 | D44: -21055.08 | E44: =_xlfn.XLOOKUP(C44,gl_cash_extract_jun2026!D:D,gl_cash_extract_jun2026!E:E,"Not Found") -> -21055.08 | F44: =IF(E44="Not Found","Missing from GL",IF(D44=E44,"Matched","Difference")) -> Matched | G44: =IF(ISNUMBER(E44),ROUND(D44-E44,2),"") -> 0
A45: 46184 | B45: CHEQUE 1076 | C45: CHQ#1076 | D45: -9101.04 | E45: =_xlfn.XLOOKUP(C45,gl_cash_extract_jun2026!D:D,gl_cash_extract_jun2026!E:E,"Not Found") -> -9101.04 | F45: =IF(E45="Not Found","Missing from GL",IF(D45=E45,"Matched","Difference")) -> Matched | G45: =IF(ISNUMBER(E45),ROUND(D45-E45,2),"") -> 0
A46: 46184 | B46: DEP ROGERS COMM AP REF40691 | C46: REF40691 | D46: 41142.46 | E46: =_xlfn.XLOOKUP(C46,gl_cash_extract_jun2026!D:D,gl_cash_extract_jun2026!E:E,"Not Found") -> 41142.46 | F46: =IF(E46="Not Found","Missing from GL",IF(D46=E46,"Matched","Difference")) -> Matched | G46: =IF(ISNUMBER(E46),ROUND(D46-E46,2),"") -> 0
A47: 46184 | B47: DEP TELUS COMM AP REF40158 | C47: REF40158 | D47: 87832.55 | E47: =_xlfn.XLOOKUP(C47,gl_cash_extract_jun2026!D:D,gl_cash_extract_jun2026!E:E,"Not Found") -> 87832.55 | F47: =IF(E47="Not Found","Missing from GL",IF(D47=E47,"Matched","Difference")) -> Matched | G47: =IF(ISNUMBER(E47),ROUND(D47-E47,2),"") -> 0
A48: 46184 | B48: PAD INTACT INS REF40786 | C48: REF40786 | D48: -22782.19 | E48: =_xlfn.XLOOKUP(C48,gl_cash_extract_jun2026!D:D,gl_cash_extract_jun2026!E:E,"Not Found") -> -22782.19 | F48: =IF(E48="Not Found","Missing from GL",IF(D48=E48,"Matched","Difference")) -> Matched | G48: =IF(ISNUMBER(E48),ROUND(D48-E48,2),"") -> 0
A49: 46185 | B49: CHEQUE 1044 | C49: CHQ#1044 | D49: -10980.23 | E49: =_xlfn.XLOOKUP(C49,gl_cash_extract_jun2026!D:D,gl_cash_extract_jun2026!E:E,"Not Found") -> -10980.23 | F49: =IF(E49="Not Found","Missing from GL",IF(D49=E49,"Matched","Difference")) -> Matched | G49: =IF(ISNUMBER(E49),ROUND(D49-E49,2),"") -> 0
A50: 46185 | B50: CHEQUE 1070 | C50: CHQ#1070 | D50: -8175.43 | E50: =_xlfn.XLOOKUP(C50,gl_cash_extract_jun2026!D:D,gl_cash_extract_jun2026!E:E,"Not Found") -> -8175.43 | F50: =IF(E50="Not Found","Missing from GL",IF(D50=E50,"Matched","Difference")) -> Matched | G50: =IF(ISNUMBER(E50),ROUND(D50-E50,2),"") -> 0
A51: 46185 | B51: CHEQUE 1072 | C51: CHQ#1072 | D51: -14804.25 | E51: =_xlfn.XLOOKUP(C51,gl_cash_extract_jun2026!D:D,gl_cash_extract_jun2026!E:E,"Not Found") -> -14804.25 | F51: =IF(E51="Not Found","Missing from GL",IF(D51=E51,"Matched","Difference")) -> Matched | G51: =IF(ISNUMBER(E51),ROUND(D51-E51,2),"") -> 0
A52: 46185 | B52: EFT BRANDT TRACTOR REF40638 | C52: REF40638 | D52: -1176.36 | E52: =_xlfn.XLOOKUP(C52,gl_cash_extract_jun2026!D:D,gl_cash_extract_jun2026!E:E,"Not Found") -> -1176.36 | F52: =IF(E52="Not Found","Missing from GL",IF(D52=E52,"Matched","Difference")) -> Matched | G52: =IF(ISNUMBER(E52),ROUND(D52-E52,2),"") -> 0
A53: 46185 | B53: PAD ENTERPRISE FLEET REF40376 | C53: REF40376 | D53: -16179.58 | E53: =_xlfn.XLOOKUP(C53,gl_cash_extract_jun2026!D:D,gl_cash_extract_jun2026!E:E,"Not Found") -> -16179.58 | F53: =IF(E53="Not Found","Missing from GL",IF(D53=E53,"Matched","Difference")) -> Matched | G53: =IF(ISNUMBER(E53),ROUND(D53-E53,2),"") -> 0
A54: 46185 | B54: POS STAPLES BUS ADV REF40167 | C54: REF40167 | D54: -2483.78 | E54: =_xlfn.XLOOKUP(C54,gl_cash_extract_jun2026!D:D,gl_cash_extract_jun2026!E:E,"Not Found") -> -2483.78 | F54: =IF(E54="Not Found","Missing from GL",IF(D54=E54,"Matched","Difference")) -> Matched | G54: =IF(ISNUMBER(E54),ROUND(D54-E54,2),"") -> 0
A55: 46188 | B55: CHEQUE 1043 | C55: CHQ#1043 | D55: -12952.95 | E55: =_xlfn.XLOOKUP(C55,gl_cash_extract_jun2026!D:D,gl_cash_extract_jun2026!E:E,"Not Found") -> -12952.95 | F55: =IF(E55="Not Found","Missing from GL",IF(D55=E55,"Matched","Difference")) -> Matched | G55: =IF(ISNUMBER(E55),ROUND(D55-E55,2),"") -> 0
... A72: 46190 | B72: DEP BELL CDA AP REF40736 | C72: REF40736 | D72: 56603.15 | E72: =_xlfn.XLOOKUP(C72,gl_cash_extract_jun2026!D:D,gl_cash_extract_jun2026!E:E,"Not Found") -> 56603.15 | F72: =IF(E72="Not Found","Missing from GL",IF(D72=E72,"Matched","Difference")) -> Matched | G72: =IF(ISNUMBER(E72),ROUND(D72-E72,2),"") -> 0
...

Sheet gl_cash_extract_jun2026
A1: Date | B1: Account | C1: Memo | D1: DocNo | E1: Amount | F1: Bank Match | G1: Reconciliation Status | H1: Difference Amount | I1: Action / Notes
A2: 46174 | B2: 1010 Cash — Operating | C2: Milton Hydro — invoice payment | D2: CHQ#1064 | E2: -8067.99 | F2: =_xlfn.XLOOKUP(Cash[[#This Row],[DocNo]],bank_statement_jun2026!C:C,bank_statement_jun2026!D:D,"Not Found") -> -8067.99 | G2: =IF(F2="Not Found","Missing from Bank",IF(ROUND(E2,2)=ROUND(F2,2),"Matched","Difference")) -> Matched | H2: =IF(ISNUMBER(F2),ROUND(E2-F2,2),"") -> 0
A3: 46174 | B3: 1010 Cash — Operating | C3: Region of Halton — invoice payment | D3: CHQ#1042 | E3: -10230.18 | F3: =_xlfn.XLOOKUP(Cash[[#This Row],[DocNo]],bank_statement_jun2026!C:C,bank_statement_jun2026!D:D,"Not Found") -> -10230.18 | G3: =IF(F3="Not Found","Missing from Bank",IF(ROUND(E3,2)=ROUND(F3,2),"Matched","Difference")) -> Matched | H3: =IF(ISNUMBER(F3),ROUND(E3-F3,2),"") -> 0
A4: 46174 | B4: 1010 Cash — Operating | C4: Rogers Communications — progress billing | D4: REF40771 | E4: 88790.68 | F4: =_xlfn.XLOOKUP(Cash[[#This Row],[DocNo]],bank_statement_jun2026!C:C,bank_statement_jun2026!D:D,"Not Found") -> 88790.68 | G4: =IF(F4="Not Found","Missing from Bank",IF(ROUND(E4,2)=ROUND(F4,2),"Matched","Difference")) -> Matched | H4: =IF(ISNUMBER(F4),ROUND(E4-F4,2),"") -> 0
A5: 46174 | B5: 1010 Cash — Operating | C5: Shell Fleet Card — invoice payment | D5: REF40144 | E5: -12217.56 | F5: =_xlfn.XLOOKUP(Cash[[#This Row],[DocNo]],bank_statement_jun2026!C:C,bank_statement_jun2026!D:D,"Not Found") -> -12217.56 | G5: =IF(F5="Not Found","Missing from Bank",IF(ROUND(E5,2)=ROUND(F5,2),"Matched","Difference")) -> Matched | H5: =IF(ISNUMBER(F5),ROUND(E5-F5,2),"") -> 0
A6: 46175 | B6: 1010 Cash — Operating | C6: Enterprise Fleet Mgmt — invoice payment | D6: REF40486 | E6: -5365.64 | F6: =_xlfn.XLOOKUP(Cash[[#This Row],[DocNo]],bank_statement_jun2026!C:C,bank_statement_jun2026!D:D,"Not Found") -> -5365.64 | G6: =IF(F6="Not Found","Missing from Bank",IF(ROUND(E6,2)=ROUND(F6,2),"Matched","Difference")) -> Matched | H6: =IF(ISNUMBER(F6),ROUND(E6-F6,2),"") -> 0
A7: 46175 | B7: 1010 Cash — Operating | C7: Telecon Design — invoice payment | D7: CHQ#1051 | E7: -17040.77 | F7: =_xlfn.XLOOKUP(Cash[[#This Row],[DocNo]],bank_statement_jun2026!C:C,bank_statement_jun2026!D:D,"Not Found") -> -17040.77 | G7: =IF(F7="Not Found","Missing from Bank",IF(ROUND(E7,2)=ROUND(F7,2),"Matched","Difference")) -> Matched | H7: =IF(ISNUMBER(F7),ROUND(E7-F7,2),"") -> 0
A8: 46175 | B8: 1010 Cash — Operating | C8: Telus network build — milestone | D8: REF40191 | E8: 88411.47 | F8: =_xlfn.XLOOKUP(Cash[[#This Row],[DocNo]],bank_statement_jun2026!C:C,bank_statement_jun2026!D:D,"Not Found") -> 88411.47 | G8: =IF(F8="Not Found","Missing from Bank",IF(ROUND(E8,2)=ROUND(F8,2),"Matched","Difference")) -> Matched | H8: =IF(ISNUMBER(F8),ROUND(E8-F8,2),"") -> 0
A9: 46176 | B9: 1010 Cash — Operating | C9: Brandt Tractor Ltd — invoice payment | D9: REF40276 | E9: -12316.92 | F9: =_xlfn.XLOOKUP(Cash[[#This Row],[DocNo]],bank_statement_jun2026!C:C,bank_statement_jun2026!D:D,"Not Found") -> -12316.92 | G9: =IF(F9="Not Found","Missing from Bank",IF(ROUND(E9,2)=ROUND(F9,2),"Matched","Difference")) -> Matched | H9: =IF(ISNUMBER(F9),ROUND(E9-F9,2),"") -> 0
A10: 46176 | B10: 1010 Cash — Operating | C10: Milton Hydro — invoice payment | D10: REF40442 | E10: -20094.18 | F10: =_xlfn.XLOOKUP(Cash[[#This Row],[DocNo]],bank_statement_jun2026!C:C,bank_statement_jun2026!D:D,"Not Found") -> -20094.18 | G10: =IF(F10="Not Found","Missing from Bank",IF(ROUND(E10,2)=ROUND(F10,2),"Matched","Difference")) -> Matched | H10: =IF(ISNUMBER(F10),ROUND(E10-F10,2),"") -> 0
A11: 46176 | B11: 1010 Cash — Operating | C11: Rogers Communications — progress billing | D11: REF40398 | E11: 102367.19 | F11: =_xlfn.XLOOKUP(Cash[[#This Row],[DocNo]],bank_statement_jun2026!C:C,bank_statement_jun2026!D:D,"Not Found") -> 102367.19 | G11: =IF(F11="Not Found","Missing from Bank",IF(ROUND(E11,2)=ROUND(F11,2),"Matched","Difference")) -> Matched | H11: =IF(ISNUMBER(F11),ROUND(E11-F11,2),"") -> 0
A12: 46176 | B12: 1010 Cash — Operating | C12: Shell Fleet Card — invoice payment | D12: CHQ#1048 | E12: -21094.19 | F12: =_xlfn.XLOOKUP(Cash[[#This Row],[DocNo]],bank_statement_jun2026!C:C,bank_statement_jun2026!D:D,"Not Found") -> -21094.19 | G12: =IF(F12="Not Found","Missing from Bank",IF(ROUND(E12,2)=ROUND(F12,2),"Matched","Difference")) -> Matched | H12: =IF(ISNUMBER(F12),ROUND(E12-F12,2),"") -> 0
A13: 46177 | B13: 1010 Cash — Operating | C13: Bell Canada — invoice payment | D13: REF40826 | E13: -4183.67 | F13: =_xlfn.XLOOKUP(Cash[[#This Row],[DocNo]],bank_statement_jun2026!C:C,bank_statement_jun2026!D:D,"Not Found") -> -4183.58 | G13: =IF(F13="Not Found","Missing from Bank",IF(ROUND(E13,2)=ROUND(F13,2),"Matched","Difference")) -> Difference | H13: =IF(ISNUMBER(F13),ROUND(E13-F13,2),"") -> -0.09 | I13: Verify source and adjust GL to bank amount; GL–bank variance -$0.09
A14: 46177 | B14: 1010 Cash — Operating | C14: Brandt Tractor Ltd — invoice payment | D14: REF40587 | E14: -6479.58 | F14: =_xlfn.XLOOKUP(Cash[[#This Row],[DocNo]],bank_statement_jun2026!C:C,bank_statement_jun2026!D:D,"Not Found") -> -6479.58 | G14: =IF(F14="Not Found","Missing from Bank",IF(ROUND(E14,2)=ROUND(F14,2),"Matched","Difference")) -> Matched | H14: =IF(ISNUMBER(F14),ROUND(E14-F14,2),"") -> 0
A15: 46177 | B15: 1010 Cash — Operating | C15: Shell Fleet Card — invoice payment | D15: REF40128 | E15: -3503.79 | F15: =_xlfn.XLOOKUP(Cash[[#This Row],[DocNo]],bank_statement_jun2026!C:C,bank_statement_jun2026!D:D,"Not Found") -> -3503.79 | G15: =IF(F15="Not Found","Missing from Bank",IF(ROUND(E15,2)=ROUND(F15,2),"Matched","Difference")) -> Matched | H15: =IF(ISNUMBER(F15),ROUND(E15-F15,2),"") -> 0
A16: 46177 | B16: 1010 Cash — Operating | C16: WESCO Distribution — invoice payment | D16: REF40326 | E16: -12272.98 | F16: =_xlfn.XLOOKUP(Cash[[#This Row],[DocNo]],bank_statement_jun2026!C:C,bank_statement_jun2026!D:D,"Not Found") -> -12272.98 | G16: =IF(F16="Not Found","Missing from Bank",IF(ROUND(E16,2)=ROUND(F16,2),"Matched","Difference")) -> Matched | H16: =IF(ISNUMBER(F16),ROUND(E16-F16,2),"") -> 0
A17: 46178 | B17: 1010 Cash — Operating | C17: Bell Canada — invoice payment | D17: CHQ#1077 | E17: -16110.81 | F17: =_xlfn.XLOOKUP(Cash[[#This Row],[DocNo]],bank_statement_jun2026!C:C,bank_statement_jun2026!D:D,"Not Found") -> -16110.81 | G17: =IF(F17="Not Found","Missing from Bank",IF(ROUND(E17,2)=ROUND(F17,2),"Matched","Difference")) -> Matched | H17: =IF(ISNUMBER(F17),ROUND(E17-F17,2),"") -> 0
A18: 46178 | B18: 1010 Cash — Operating | C18: Bell aerial build — holdback release | D18: REF40634 | E18: 77425.86 | F18: =_xlfn.XLOOKUP(Cash[[#This Row],[DocNo]],bank_statement_jun2026!C:C,bank_statement_jun2026!D:D,"Not Found") -> 77425.86 | G18: =IF(F18="Not Found","Missing from Bank",IF(ROUND(E18,2)=ROUND(F18,2),"Matched","Difference")) -> Matched | H18: =IF(ISNUMBER(F18),ROUND(E18-F18,2),"") -> 0
A19: 46178 | B19: 1010 Cash — Operating | C19: GFL Environmental — invoice payment | D19: REF40334 | E19: -14685.67 | F19: =_xlfn.XLOOKUP(Cash[[#This Row],[DocNo]],bank_statement_jun2026!C:C,bank_statement_jun2026!D:D,"Not Found") -> -14685.67 | G19: =IF(F19="Not Found","Missing from Bank",IF(ROUND(E19,2)=ROUND(F19,2),"Matched","Difference")) -> Matched | H19: =IF(ISNUMBER(F19),ROUND(E19-F19,2),"") -> 0
A20: 46178 | B20: 1010 Cash — Operating | C20: Shell Fleet Card — invoice payment | D20: REF40539 | E20: -6506.94 | F20: =_xlfn.XLOOKUP(Cash[[#This Row],[DocNo]],bank_statement_jun2026!C:C,bank_statement_jun2026!D:D,"Not Found") -> -6506.94 | G20: =IF(F20="Not Found","Missing from Bank",IF(ROUND(E20,2)=ROUND(F20,2),"Matched","Difference")) -> Matched | H20: =IF(ISNUMBER(F20),ROUND(E20-F20,2),"") -> 0
A21: 46181 | B21: 1010 Cash — Operating | C21: Bell Canada — invoice payment | D21: REF40379 | E21: -14193.51 | F21: =_xlfn.XLOOKUP(Cash[[#This Row],[DocNo]],bank_statement_jun2026!C:C,bank_statement_jun2026!D:D,"Not Found") -> -14193.51 | G21: =IF(F21="Not Found","Missing from Bank",IF(ROUND(E21,2)=ROUND(F21,2),"Matched","Difference")) -> Matched | H21: =IF(ISNUMBER(F21),ROUND(E21-F21,2),"") -> 0
A22: 46181 | B22: 1010 Cash — Operating | C22: Bell aerial build — holdback release | D22: REF40527 | E22: 109123.56 | F22: =_xlfn.XLOOKUP(Cash[[#This Row],[DocNo]],bank_statement_jun2026!C:C,bank_statement_jun2026!D:D,"Not Found") -> 109123.56 | G22: =IF(F22="Not Found","Missing from Bank",IF(ROUND(E22,2)=ROUND(F22,2),"Matched","Difference")) -> Matched | H22: =IF(ISNUMBER(F22),ROUND(E22-F22,2),"") -> 0
A23: 46181 | B23: 1010 Cash — Operating | C23: Bell aerial build — holdback release | D23: REF40561 | E23: 104277.78 | F23: =_xlfn.XLOOKUP(Cash[[#This Row],[DocNo]],bank_statement_jun2026!C:C,bank_statement_jun2026!D:D,"Not Found") -> 104277.78 | G23: =IF(F23="Not Found","Missing from Bank",IF(ROUND(E23,2)=ROUND(F23,2),"Matched","Difference")) -> Matched | H23: =IF(ISNUMBER(F23),ROUND(E23-F23,2),"") -> 0
A24: 46181 | B24: 1010 Cash — Operating | C24: Ditch Witch of Ontario — invoice payment | D24: CHQ#1053 | E24: -19414.58 | F24: =_xlfn.XLOOKUP(Cash[[#This Row],[DocNo]],bank_statement_jun2026!C:C,bank_statement_jun2026!D:D,"Not Found") -> -19414.58 | G24: =IF(F24="Not Found","Missing from Bank",IF(ROUND(E24,2)=ROUND(F24,2),"Matched","Difference")) -> Matched | H24: =IF(ISNUMBER(F24),ROUND(E24-F24,2),"") -> 0
A25: 46181 | B25: 1010 Cash — Operating | C25: Enterprise Fleet Mgmt — invoice payment | D25: REF40206 | E25: -23647.98 | F25: =_xlfn.XLOOKUP(Cash[[#This Row],[DocNo]],bank_statement_jun2026!C:C,bank_statement_jun2026!D:D,"Not Found") -> -23647.98 | G25: =IF(F25="Not Found","Missing from Bank",IF(ROUND(E25,2)=ROUND(F25,2),"Matched","Difference")) -> Matched | H25: =IF(ISNUMBER(F25),ROUND(E25-F25,2),"") -> 0
... A54: 46185 | B54: 1010 Cash — Operating | C54: Enterprise Fleet Mgmt — invoice payment | D54: REF40376 | E54: -16179.58 | F54: =_xlfn.XLOOKUP(Cash[[#This Row],[DocNo]],bank_statement_jun2026!C:C,bank_statement_jun2026!D:D,"Not Found") -> -16179.58 | G54: =IF(F54="Not Found","Missing from Bank",IF(ROUND(E54,2)=ROUND(F54,2),"Matched","Difference")) -> Matched | H54: =IF(ISNUMBER(F54),ROUND(E54-F54,2),"") -> 0
A55: 46185 | B55: 1010 Cash — Operating | C55: GFL Environmental — invoice payment | D55: REF40929 | E55: -743.29 | F55: =_xlfn.XLOOKUP(Cash[[#This Row],[DocNo]],bank_statement_jun2026!C:C,bank_statement_jun2026!D:D,"Not Found") -> -743.6 | G55: =IF(F55="Not Found","Missing from Bank",IF(ROUND(E55,2)=ROUND(F55,2),"Matched","Difference")) -> Difference | H55: =IF(ISNUMBER(F55),ROUND(E55-F55,2),"") -> 0.31 | I55: Verify source and adjust GL to bank amount; GL–bank variance $0.31
A56: 46185 | B56: 1010 Cash — Operating | C56: Petro-Canada SuperPass — invoice payment | D56: CHQ#1044 | E56: -10980.23 | F56: =_xlfn.XLOOKUP(Cash[[#This Row],[DocNo]],bank_statement_jun2026!C:C,bank_statement_jun2026!D:D,"Not Found") -> -10980.23 | G56: =IF(F56="Not Found","Missing from Bank",IF(ROUND(E56,2)=ROUND(F56,2),"Matched","Difference")) -> Matched | H56: =IF(ISNUMBER(F56),ROUND(E56-F56,2),"") -> 0
A57: 46185 | B57: 1010 Cash — Operating | C57: Staples Business — invoice payment | D57: REF40167 | E57: -2483.78 | F57: =_xlfn.XLOOKUP(Cash[[#This Row],[DocNo]],bank_statement_jun2026!C:C,bank_statement_jun2026!D:D,"Not Found") -> -2483.78 | G57: =IF(F57="Not Found","Missing from Bank",IF(ROUND(E57,2)=ROUND(F57,2),"Matched","Difference")) -> Matched | H57: =IF(ISNUMBER(F57),ROUND(E57-F57,2),"") -> 0
A58: 46188 | B58: 1010 Cash — Operating | C58: Bell Canada — invoice payment | D58: REF40721 | E58: -15901.99 | F58: =_xlfn.XLOOKUP(Cash[[#This Row],[DocNo]],bank_statement_jun2026!C:C,bank_statement_jun2026!D:D,"Not Found") -> -15901.99 | G58: =IF(F58="Not Found","Missing from Bank",IF(ROUND(E58,2)=ROUND(F58,2),"Matched","Difference")) -> Matched | H58: =IF(ISNUMBER(F58),ROUND(E58-F58,2),"") -> 0
A59: 46188 | B59: 1010 Cash — Operating | C59: Home Depot Pro — invoice payment | D59: REF40412 | E59: -8619.37 | F59: =_xlfn.XLOOKUP(Cash[[#This Row],[DocNo]],bank_statement_jun2026!C:C,bank_statement_jun2026!D:D,"Not Found") -> -8619.37 | G59: =IF(F59="Not Found","Missing from Bank",IF(ROUND(E59,2)=ROUND(F59,2),"Matched","Difference")) -> Matched | H59: =IF(ISNUMBER(F59),ROUND(E59-F59,2),"") -> 0
A60: 46188 | B60: 1010 Cash — Operating | C60: Home Depot Pro — invoice payment | D60: CHQ#1054 | E60: -4550.69 | F60: =_xlfn.XLOOKUP(Cash[[#This Row],[DocNo]],bank_statement_jun2026!C:C,bank_statement_jun2026!D:D,"Not Found") -> -4550.69 | G60: =IF(F60="Not Found","Missing from Bank",IF(ROUND(E60,2)=ROUND(F60,2),"Matched","Difference")) -> Matched | H60: =IF(ISNUMBER(F60),ROUND(E60-F60,2),"") -> 0
A61: 46188 | B61: 1010 Cash — Operating | C61: Milton Hydro — invoice payment | D61: REF40659 | E61: -21240.09 | F61: =_xlfn.XLOOKUP(Cash[[#This Row],[DocNo]],bank_statement_jun2026!C:C,bank_statement_jun2026!D:D,"Not Found") -> -21240.09 | G61: =IF(F61="Not Found","Missing from Bank",IF(ROUND(E61,2)=ROUND(F61,2),"Matched","Difference")) -> Matched | H61: =IF(ISNUMBER(F61),ROUND(E61-F61,2),"") -> 0
A62: 46188 | B62: 1010 Cash — Operating | C62: Rogers Communications — invoice payment | D62: REF40238 | E62: -19356.19 | F62: =_xlfn.XLOOKUP(Cash[[#This Row],[DocNo]],bank_statement_jun2026!C:C,bank_statement_jun2026!D:D,"Not Found") -> -19356.19 | G62: =IF(F62="Not Found","Missing from Bank",IF(ROUND(E62,2)=ROUND(F62,2),"Matched","Difference")) -> Matched | H62: =IF(ISNUMBER(F62),ROUND(E62-F62,2),"") -> 0
A63: 46188 | B63: 1010 Cash — Operating | C63: Staples Business — invoice payment | D63: REF40284 | E63: -9270.17 | F63: =_xlfn.XLOOKUP(Cash[[#This Row],[DocNo]],bank_statement_jun2026!C:C,bank_statement_jun2026!D:D,"Not Found") -> -9270.17 | G63: =IF(F63="Not Found","Missing from Bank",IF(ROUND(E63,2)=ROUND(F63,2),"Matched","Difference")) -> Matched | H63: =IF(ISNUMBER(F63),ROUND(E63-F63,2),"") -> 0
A64: 46188 | B64: 1010 Cash — Operating | C64: Vermeer Canada — invoice payment | D64: CHQ#1043 | E64: -12952.95 | F64: =_xlfn.XLOOKUP(Cash[[#This Row],[DocNo]],bank_statement_jun2026!C:C,bank_statement_jun2026!D:D,"Not Found") -> -12952.95 | G64: =IF(F64="Not Found","Missing from Bank",IF(ROUND(E64,2)=ROUND(F64,2),"Matched","Difference")) -> Matched | H64: =IF(ISNUMBER(F64),ROUND(E64-F64,2),"") -> 0
A65: 46188 | B65: 1010 Cash — Operating | C65: Vermeer Canada — invoice payment | D65: REF40614 | E65: -13321.03 | F65: =_xlfn.XLOOKUP(Cash[[#This Row],[DocNo]],bank_statement_jun2026!C:C,bank_statement_jun2026!D:D,"Not Found") -> -13321.03 | G65: =IF(F65="Not Found","Missing from Bank",IF(ROUND(E65,2)=ROUND(F65,2),"Matched","Difference")) -> Matched | H65: =IF(ISNUMBER(F65),ROUND(E65-F65,2),"") -> 0
A66: 46188 | B66: 1010 Cash — Operating | C66: WSIB Ontario — invoice payment | D66: CHQ#1047 | E66: -2837.17 | F66: =_xlfn.XLOOKUP(Cash[[#This Row],[DocNo]],bank_statement_jun2026!C:C,bank_statement_jun2026!D:D,"Not Found") -> -2837.17 | G66: =IF(F66="Not Found","Missing from Bank",IF(ROUND(E66,2)=ROUND(F66,2),"Matched","Difference")) -> Matched | H66: =IF(ISNUMBER(F66),ROUND(E66-F66,2),"") -> 0
A67: 46189 | B67: 1010 Cash — Operating | C67: Milton Hydro — invoice payment | D67: CHQ#1056 | E67: -15945.77 | F67: =_xlfn.XLOOKUP(Cash[[#This Row],[DocNo]],bank_statement_jun2026!C:C,bank_statement_jun2026!D:D,"Not Found") -> -15945.77 | G67: =IF(F67="Not Found","Missing from Bank",IF(ROUND(E67,2)=ROUND(F67,2),"Matched","Difference")) -> Matched | H67: =IF(ISNUMBER(F67),ROUND(E67-F67,2),"") -> 0
... A79: 46191 | B79: 1010 Cash — Operating | C79: Shell Fleet Card — invoice payment | D79: CHQ#1078 | E79: -3495.61 | F79: =_xlfn.XLOOKUP(Cash[[#This Row],[DocNo]],bank_statement_jun2026!C:C,bank_statement_jun2026!D:D,"Not Found") -> -3495.61 | G79: =IF(F79="Not Found","Missing from Bank",IF(ROUND(E79,2)=ROUND(F79,2),"Matched","Difference")) -> Matched | H79: =IF(ISNUMBER(F79),ROUND(E79-F79,2),"") -> 0
...
